<mujoco>
        <option gravity="0 0 -17.9"/>
        <worldbody>
            <light diffuse="0.5 0.5 0.5" pos="0 0 3" dir="0 0 -1"/>
            <!-- Big Plane -->
            <body name="surface" pos="-10 0 0">
                <geom type="plane" size="30 30 0.1" rgba="0.7 0.7 0.7 1" friction="1 1 1"/>
            </body>

            <!-- Fixed anchor point -->
            <body name="anchor" pos="0 0 6">
                <!-- Pendulum body -->
                <body name="pendulum" pos="0 0 -2.5">
                    <joint name="hinge" type="hinge" axis="1 0 0"/>
                    <geom type="cylinder" size="0.005 0.005" fromto="0 0 0 0 0 -1" density="10"/>
                </body>
            </body>

            <!-- Unknown mass -->
            <body name="hollow_sphere" pos="0 0 0">
                <geom type="sphere" size="0.05" density="0.7" rgba="0 0 1 1"/>
                <joint name="hollow_sphere_joint" type="free"/>
            </body>
        </worldbody>
    </mujoco>
