<mujoco>
    <worldbody>
        <!-- Base pivot -->
        <body name="pivot1" pos="0 0 0">
            <joint name="joint1" type="hinge" axis="0 0 1" />
            <geom type="sphere" size="0.1" rgba="0.8 0.2 0.2 1" />
            
            <!-- First pendulum link -->
            <body name="link1" pos="0 -1 0">
                <geom type="capsule" size="0.05 1" rgba="0.2 0.8 0.2 1" />
                <joint name="joint2" type="hinge" axis="0 0 1" />
                
                <!-- Second pendulum link -->
                <body name="link2" pos="0 -1 0">
                    <geom type="capsule" size="0.05 1" rgba="0.2 0.2 0.8 1" />
                </body>
            </body>
        </body>
    </worldbody>
    
    <!-- Physics settings -->
    <option timestep="0.01" />
    <size njmax="500" nconmax="100" />
</mujoco>
