<mujoco model="rotating_rod">
    <option gravity="0 0 -9.81"/>
    
    <worldbody>
        <light diffuse=".5 .5 .5" pos="0 0 3" dir="0 0 -1"/>
        <geom type="plane" size="5 5 0.1" rgba=".9 .9 .9 1"/>
        
        <body pos="0 0 1" euler="0 0 0">
            <joint type="hinge" axis="0 0 1" name="hinge"/>
            <geom type="capsule" size="0.05 0.75" mass="2" rgba=".8 .2 .1 1"/>
        </body>
    </worldbody>

    <actuator>
        <motor joint="hinge" name="torque" gear="1" ctrllimited="true" ctrlrange="-10 10"/>
    </actuator>

    <sensor>
        <jointvel joint="hinge" name="hinge_vel"/>
    </sensor>
</mujoco>
